Traceback (most recent call last):
  File "/Users/hernando/opt/anaconda3/lib/python3.9/site-packages/jupyter_cache/executors/utils.py", line 51, in single_nb_execution
    executenb(
  File "/Users/hernando/opt/anaconda3/lib/python3.9/site-packages/nbclient/client.py", line 1204, in execute
    return NotebookClient(nb=nb, resources=resources, km=km, **kwargs).execute()
  File "/Users/hernando/opt/anaconda3/lib/python3.9/site-packages/nbclient/util.py", line 84, in wrapped
    return just_run(coro(*args, **kwargs))
  File "/Users/hernando/opt/anaconda3/lib/python3.9/site-packages/nbclient/util.py", line 62, in just_run
    return loop.run_until_complete(coro)
  File "/Users/hernando/opt/anaconda3/lib/python3.9/asyncio/base_events.py", line 647, in run_until_complete
    return future.result()
  File "/Users/hernando/opt/anaconda3/lib/python3.9/site-packages/nbclient/client.py", line 663, in async_execute
    await self.async_execute_cell(
  File "/Users/hernando/opt/anaconda3/lib/python3.9/site-packages/nbclient/client.py", line 965, in async_execute_cell
    await self._check_raise_for_error(cell, cell_index, exec_reply)
  File "/Users/hernando/opt/anaconda3/lib/python3.9/site-packages/nbclient/client.py", line 862, in _check_raise_for_error
    raise CellExecutionError.from_cell_and_msg(cell, exec_reply_content)
nbclient.exceptions.CellExecutionError: An error occurred while executing the following cell:
------------------
idx        = np.random.choice(range(len(y_test)), 1)[0]
image      = X_test[idx]
prediction = predicted[idx]
test       = y_test[idx]
image = image.reshape(8, 8)
plt.imshow(image, cmap=plt.cm.gray_r)
plt.title(f'Prediction: {prediction}')
plt.show()
input('Continue (y/n) ?')
print(f'True: {test}')
------------------

[0;31m---------------------------------------------------------------------------[0m
[0;31mStdinNotImplementedError[0m                  Traceback (most recent call last)
[0;32m/var/folders/56/_pmdccc97ljb_l3v3s6gkrxm0000gn/T/ipykernel_8577/4236989993.py[0m in [0;36m<module>[0;34m[0m
[1;32m      7[0m [0mplt[0m[0;34m.[0m[0mtitle[0m[0;34m([0m[0;34mf'Prediction: {prediction}'[0m[0;34m)[0m[0;34m[0m[0;34m[0m[0m
[1;32m      8[0m [0mplt[0m[0;34m.[0m[0mshow[0m[0;34m([0m[0;34m)[0m[0;34m[0m[0;34m[0m[0m
[0;32m----> 9[0;31m [0minput[0m[0;34m([0m[0;34m'Continue (y/n) ?'[0m[0;34m)[0m[0;34m[0m[0;34m[0m[0m
[0m[1;32m     10[0m [0mprint[0m[0;34m([0m[0;34mf'True: {test}'[0m[0;34m)[0m[0;34m[0m[0;34m[0m[0m

[0;32m~/opt/anaconda3/lib/python3.9/site-packages/ipykernel/kernelbase.py[0m in [0;36mraw_input[0;34m(self, prompt)[0m
[1;32m   1172[0m         """
[1;32m   1173[0m         [0;32mif[0m [0;32mnot[0m [0mself[0m[0;34m.[0m[0m_allow_stdin[0m[0;34m:[0m[0;34m[0m[0;34m[0m[0m
[0;32m-> 1174[0;31m             raise StdinNotImplementedError(
[0m[1;32m   1175[0m                 [0;34m"raw_input was called, but this frontend does not support input requests."[0m[0;34m[0m[0;34m[0m[0m
[1;32m   1176[0m             )

[0;31mStdinNotImplementedError[0m: raw_input was called, but this frontend does not support input requests.
StdinNotImplementedError: raw_input was called, but this frontend does not support input requests.

